Workbook

Sheet Sheet1
B1: Cantidad | C1: Medida | D1: Precio unidad | E1: Precio total
A2: Pescado | B2: 5 | C2: KG | D2: 9500 | E2: =D2*B2 -> 47500 | L2: Pendientes
A3: Cebolla Morada | B3: 1100 | C3: KG | D3: 2100 | E3: 2300
A4: Culantro castilla | B4: 10 | C4: Rollo | D4: 150 | E4: =D4*B4 -> 1500 | L4: Cucharas
A5: Chiles dulces | B5: 3 | C5: Unidad | D5: 200 | E5: =D5*B5 -> 600 | L5: Salsas
A6: Taza 8 oz | B6: 50 | C6: Unidad | D6: 90 | E6: =D6*B6 -> 4500 | L6: Gin
A7: Taza 16 oz | B7: 25 | C7: Unidad | D7: 115 | E7: =D7*B7 -> 2875 | L7: Limon
A8: Limon | B8: 75 | C8: Unidad | D8: 80 | E8: =D8*B8 -> 6000 | L8: Ranchitas
A9: Gin | B9: 1 | C9: L | D9: 2000 | L9: Chile
A10: Tortilla tostada | B10: 900 | C10: gms | E10: 5000
A11: Ranchita | B11: 30 | C11: paquete | D11: 150 | E11: =D11*B11 -> 4500
A12: Chiles panameño | B12: 3 | D12: 150 | E12: =D12*B12 -> 450
A13: Salsas
A14: Cucharas
A15: etiquetas | B15: 60 | D15: 70 | E15: =D15*B15 -> 4200
A16: Total | E16: =SUM(E2:E15) -> 79425
A23: Datos | B23: 120g | C23: Pescado | D23: 8oz
B24: 107g | C24: Caldo | D24: 8oz

Sheet Costo materia prima
A3: Nombre | B3: Unidad medible | C3: Precio | D3: Peso bruto | E3: Peso neto
A4: Culantro | B4: rollo | C4: 330 | D4: 105gms | E4: 96gms
A5: Cebolla morada | B5: KG | C5: 2250 | D5: 650gms | E5: 414gms | F5: 64% rendimiento
A6: Cebolla blanca | B6: KG | C6: 1020 | D6: 444 gms | E6: 300gms
A7: Chile dulce | B7: Unidad | C7: 300 | D7: 432gms | E7: 351gms (4 chiles)
A8: Apio* | B8: KG | C8: 1190 | D8: 115gms | E8: 76 gms
A9: Gengibre | B9: KG | C9: 1870 | D9: 120gms | E9: 74gms
A10: Manga | B10: KG | C10: 550 | D10: 520gms | E10: 330gms
A11: Piña | B11: KG | C11: 1000 | D11: 1005gms
A12: Pescado más caldo | B12: KG | C12: 29800 | D12: 3000gms + el respectivo caldo
A13: tortillas tostadas | B13: kg | C13: 4600
E21: Muestra
A22: Proporción
A34: 100gms de olores

Sheet Ceviche tradicional
A1: Muestra 1
B3: 180gms de pescado
B4: 100 gms de olores | C4: 280 Pescado mas olores
B5: 230 ml caldo
B7: 420 el total
A10: 🐟 Pescado: 180g
A11: 🧅 Cebolla: 50g
A12: 🌶 Chile dulce: 20g
A13: 🌿 Apio: 5gms
A14: 🌱 Culantro: 10g
A15: Cebolla morada 5gms

Sheet Ceviche con gengibre
A8: 🐟 Pescado: 240g
A9: 🧅 Cebolla: 50g
A10: 🌶 Chile dulce: 20g
A11: 🌿 Apio: 5gms
A12: 🌱 Culantro: 10g
A13: Cebolla morada 10gms
A14: gengibre | B14: 1gm
A15: caldo | B15: dos de 4 oz
B17: 434

Sheet ceviche con mango
A4: presentacion | B4: 200gms
A6: Pescado | B6: 90gms
A7: cebolla | B7: 25 gms
A8: chile dulce | B8: 10gms
A9: apio | B9: 2gms
A10: culantro | B10: 5 gms
A11: Mango | B11: 20gms
A12: caldo | B12: 1 de 4 oz

Sheet ceviche con piña
A5: presentacion | B5: 200gms
A7: Pescado | B7: 90gms
A8: cebolla | B8: 25 gms
A9: chile dulce | B9: 10gms
A10: apio | B10: 2gms
A11: culantro | B11: 5 gms
A12: Mango | B12: 20gms
A13: caldo | B13: 1 de 4 oz

Sheet Gastos Mensuales activos
A7: Tortillas | B7: 4500
A8: Ceviche | B8: 29800
A9: Telefono celular | B9: 30000
A10: Total | B10: =SUM(B7:B9) -> 64300

Sheet Realizados
A1: Total
A3: Ceviches Grandes | B3: 2
A4: Ceviches pequenos | B4: 3

Sheet Proporciones recomendables
A2: Presentación 200 gms
A3: 🐟 Pescado: 100g
A4: 🧅 Cebolla (mezcla blanca+morada): 40g
A5: 🌶 Chile dulce: 15g
A6: 🌿 Apio: 5g
A7: 🌱 Culantro: 5g
A8: 🍋 Caldo: 30–40g (CLAVE para volumen y sabor)
A9: 🍍/🥭 toppings: 10–20g opcional
A11: 👉 Total: ~200g

Sheet Receta Ajustada Marzo 30
F6: Pequeño /gr | G6: Grande /gr | J6: Pequeño /gr | K6: % | L6: Grande /gr | M6: % | N6: Familiar
E7: Peso neto | F7: 277 | G7: 464 | I7: Peso neto | J7: =J8-J9 -> 237 | K7: =J7/J8 -> 0.948 | L7: =L8-L9 -> 454 | M7: =L7/L8 -> 0.94583333
E8: Peso bruto | F8: =F14+F9 -> 290 | G8: 490 | I8: Peso bruto | J8: 250 | K8: 1 | L8: 480 | M8: 1
E9: Peso taza con tapa | F9: 13 | G9: 26 | I9: Peso taza con tapa | J9: 13 | K9: =J9/J8 -> 0.052 | L9: 26 | M9: =L9/L8 -> 0.054166667
E10: Pescado | F10: 90 | G10: 180 | I10: Pescado | J10: 100 | K10: =J10/J14 -> 0.42194093 | L10: 195 | M10: =L10/L14 -> 0.42951542
E11: Olores mezcla | F11: 50 | G11: 100 | I11: Olores mezcla | J11: 36 | K11: =J11/J14 -> 0.15189873 | L11: 66 | M11: =L11/L14 -> 0.14537445
E12: Caldo | F12: =59.5+77 -> 136.5 | G12: =119+64 -> 183 | I12: Caldo | J12: 100 | K12: =J12/J14 -> 0.42194093 | L12: 190 | M12: =L12/L14 -> 0.4185022
E13: Otros | F13: 0.5 | G13: 1 | I13: Otros | J13: 1 | K13: =J13/J12 -> 0.01 | L13: 3 | M13: =L13/L14 -> 0.0066079295
E14: Peso. Neto | F14: =F10+F11+F12+F13 -> 277 | G14: =G10+G11+G12+G13 -> 464 | I14: Peso. Neto | J14: =J10+J11+J12+J13 -> 237 | L14: =L10+L11+L12+L13 -> 454
J15: =J14+J9 -> 250 | L15: =L14+L9 -> 480
J16: 1 onz = 28,35 gr
J17: Pequeño /onz | K17: % | L17: Grande /onz | M17: % | N17: Familiar | P17: %
I18: Peso neto | J18: =J7/28.35 -> 8.3597884 | K18: =J18/J19 -> 0.948 | L18: =L7/28.35 -> 16.014109 | M18: =L18/L19 -> 0.94583333 | N18: 22
I19: Peso bruto | J19: =J8/28.35 -> 8.8183422 | K19: 1 | L19: =L8/28.35 -> 16.931217 | M19: 1 | N19: =N18+N20 -> 22.88 | P19: 100
I20: Peso taza con tapa | J20: =J9/28.35 -> 0.45855379 | K20: =J20/J19 -> 0.052 | L20: =L9/28.35 -> 0.91710758 | M20: =L20/L19 -> 0.054166667 | N20: =N18*0.04 -> 0.88
I21: Pescado | J21: =J10/28.35 -> 3.5273369 | K21: =J21/J25 -> 0.42194093 | L21: =L10/28.35 -> 6.8783069 | M21: =L21/L25 -> 0.42951542 | N21: =N18*M21 -> 9.4493392
I22: Olores mezcla | J22: =J11/28.35 -> 1.2698413 | K22: =J22/J25 -> 0.15189873 | L22: =L11/28.35 -> 2.3280423 | M22: =L22/L25 -> 0.14537445 | N22: =M22*N19 -> 3.3261674
I23: Caldo | J23: =J12/28.35 -> 3.5273369 | K23: =J23/J25 -> 0.42194093 | L23: =L12/28.35 -> 6.70194 | M23: =L23/L25 -> 0.4185022 | N23: =N18*M23 -> 9.2070485
I24: Otros | J24: =J13/28.35 -> 0.035273369 | K24: =J24/J23 -> 0.01 | L24: =L13/28.35 -> 0.10582011 | M24: =L24/L25 -> 0.0066079295 | N24: =N18*M24 -> 0.14537445
I25: Peso. Neto | J25: =J14/28.35 -> 8.3597884 | L25: =L14/28.35 -> 16.014109
J26: =J15/28.35 -> 8.8183422 | L26: =L15/28.35 -> 16.931217
G28: Precio M&S | J28: 3100 | L28: 5600 | N28: 7100
G29: Precio Esqunita | J29: 2800 | L29: 5200 | N29: 6800
G30: DIF | J30: =J28-J29 -> 300 | L30: =L28-L29 -> 400 | N30: =N28-N29 -> 300
J31: 2850 | L31: 5350 | N31: 6950
J34: =J19 -> 8.8183422 | K34: =L19 -> 16.931217 | L34: 22
K35: =K34-J34 -> 8.1128748 | L35: =L34-K34 -> 5.0687831
K36: Clásico | L36: Mixto camarón | M36: Tropical | N36: Camarón
J37: 8 | K37: 2850 | L37: 3350 | M37: 3000
J38: 12 | K38: 4350 | L38: 4850 | M38: 4500
J39: 16 | K39: 5350 | L39: 5850 | M39: 5650
J40: 22 | K40: 7100 | L40: 8200 | M40: 7650

Sheet Mezclas por tamaño
A1: CLASICO | O1: *Otro = Mango , Piña o Camaron
A2: presentacion | B2: 200gms | C2: 200 | F2: 1. Ceviche Clásico | T2: % Ingredientes
B3: Original | G3: Oz | H3: Gr | I3: Pescado | J3: Caldo | K3: Cebolla B | L3: Culantro | M3: Chile D | N3: Gengibre | O3: Apio | P3: Cebolla M | Q3: Otro* | R3: Total Picadura | T3: Picadura | U3: Caldo | V3: Pescado | W3: Otro | X3: Total
A4: Pescado | B4: 90gms | C4: 75 | D4: =C4/C2 -> 0.375 | F4: 1 | G4: 8 | H4: =G4*28.35 -> 226.8 | I4: =H4*D4 -> 85.05 | J4: =H4*D10 -> 79.38 | K4: =H4*D5 -> 22.68 | L4: =H4*D8 -> 11.34 | M4: =H4*D6 -> 19.278 | N4: =H4*D11 -> 1.134 | O4: =H4*D7 -> 2.268 | P4: =H4*D12 -> 5.67 | R4: =+K4+L4+M4+O4 -> 55.566 | T4: =R4/H4 -> 0.245 | U4: =J4/H4 -> 0.35 | V4: =I4/H4 -> 0.375 | W4: =(N4+P4+Q4)/H4 -> 0.03 | X4: =SUM(T4:W4) -> 1
A5: cebolla B | B5: 25 gms | C5: 20 | D5: =C5/C2 -> 0.1 | F5: 2 | G5: 12 | H5: =G5*28.35 -> 340.2 | I5: =H5*D4 -> 127.575 | J5: =H5*D10 -> 119.07 | K5: =H5*D5 -> 34.02 | L5: =H5*D8 -> 17.01 | M5: =H5*D6 -> 28.917 | N5: =H5*D11 -> 1.701 | O5: =H5*D7 -> 3.402 | P5: =H5*D12 -> 8.505 | R5: =+K5+L5+M5+O5 -> 83.349 | T5: =R5/H5 -> 0.245 | U5: =J5/H5 -> 0.35 | V5: =I5/H5 -> 0.375 | W5: =(N5+P5+Q5)/H5 -> 0.03 | X5: =SUM(T5:W5) -> 1
A6: chile dulce | B6: 10gms | C6: 17 | D6: =C6/C2 -> 0.085 | F6: 3 | G6: 16 | H6: =G6*28.35 -> 453.6 | I6: =H6*D4 -> 170.1 | J6: =H6*D10 -> 158.76 | K6: =H6*D5 -> 45.36 | L6: =H6*D8 -> 22.68 | M6: =H6*D6 -> 38.556 | N6: =H6*D11 -> 2.268 | O6: =H6*D7 -> 4.536 | P6: =H6*D12 -> 11.34 | R6: =+K6+L6+M6+O6 -> 111.132 | T6: =R6/H6 -> 0.245 | U6: =J6/H6 -> 0.35 | V6: =I6/H6 -> 0.375 | W6: =(N6+P6+Q6)/H6 -> 0.03 | X6: =SUM(T6:W6) -> 1
A7: apio | B7: 2gms | C7: 2 | D7: =C7/C2 -> 0.01 | F7: 4 | G7: 22 | H7: =G7*28.35 -> 623.7 | I7: =H7*D4 -> 233.8875 | J7: =H7*D10 -> 218.295 | K7: =H7*D5 -> 62.37 | L7: =H7*D8 -> 31.185 | M7: =H7*D6 -> 53.0145 | N7: =H7*D11 -> 3.1185 | O7: =H7*D7 -> 6.237 | P7: =H7*D12 -> 15.5925 | R7: =+K7+L7+M7+O7 -> 152.8065 | T7: =R7/H7 -> 0.245 | U7: =J7/H7 -> 0.35 | V7: =I7/H7 -> 0.375 | W7: =(N7+P7+Q7)/H7 -> 0.03 | X7: =SUM(T7:W7) -> 1
A8: culantro | B8: 5 gms | C8: 10 | D8: =C8/C2 -> 0.05
A9: Mango | B9: 20gms | G9: Precios
A10: caldo | B10: 1 de 4 oz | C10: 70 | D10: =C10/C2 -> 0.35 | G10: Oz | H10: Gr | I10: Precio | J10: Precio/ OZ | K10: Precio /gr pescado | L10: Costo Pescado | M10: Margen | O10: Costo de Pescado
A11: Gengibre | B11: 1 gr | C11: 1 | D11: =C11/C2 -> 0.005 | F11: 1 | G11: 8 | H11: =G11*28.35 -> 226.8 | I11: 2850 | J11: =I11/G11 -> 356.25 | K11: =I11/I4 -> 33.5097 | L11: =I4*V13 -> 844.373 | M11: =(I11-L11)/I11 -> 0.70372877 | O11: Tambor de pescado de 5 Litros / 3kg de pescado = | V11: 29783.88
A12: Cebolla Morada | B12: 2 gr | C12: 5 | D12: =C12/C2 -> 0.025 | F12: 2 | G12: 12 | H12: =G12*28.35 -> 340.2 | I12: 4200 | J12: =I12/G12 -> 350 | K12: =I12/I5 -> 32.921811 | L12: =I5*V13 -> 1266.5595 | M12: =(I12-L12)/I12 -> 0.69843821 | O12: Precio Kilo de Pescado | V12: =V11/3 -> 9927.96
C13: =+C4+C5+C6+C7+C8+C11+C10+C12 -> 200 | D13: =+D4+D5+D6+D7+D8+D11+D10+D12 -> 1 | F13: 3 | G13: 16 | H13: =G13*28.35 -> 453.6 | I13: 5350 | J13: =I13/G13 -> 334.375 | K13: =I13/I6 -> 31.452087 | L13: =I6*V13 -> 1688.746 | M13: =(I13-L13)/I13 -> 0.68434654 | O13: Precio/ gramo | V13: =V12/1000 -> 9.92796
F14: 4 | G14: 22 | H14: =G14*28.35 -> 623.7 | I14: 7100 | J14: =I14/G14 -> 322.72727 | K14: =I14/I7 -> 30.356475 | L14: =I7*V13 -> 2322.0257 | M14: =(I14-L14)/I14 -> 0.67295412
A16: TROPICAL (Mango o Piña)
A17: presentacion | B17: 200gms | C17: 200 | F17: 2. Ceviche Tropical | T17: % Ingredientes
B18: Original | G18: Oz | H18: Gr | I18: Pescado | J18: Caldo | K18: Cebolla B | L18: Culantro | M18: Chile D | N18: Gengibre | O18: Apio | P18: Cebolla M | Q18: Otro* | R18: Total Picadura | T18: Picadura | U18: Caldo | V18: Pescado | W18: Otro | X18: Total
A19: Pescado | B19: 90gms | C19: 65 | D19: =C19/C17 -> 0.325 | F19: 1 | G19: 8 | H19: =G19*28.35 -> 226.8 | I19: =H19*D19 -> 73.71 | J19: =H19*D25 -> 79.38 | K19: =H19*D20 -> 19.278 | L19: =H19*D23 -> 9.072 | M19: =H19*D21 -> 15.876 | N19: =H19*D26 -> 1.134 | O19: =H19*D22 -> 2.268 | P19: =H19*D27 -> 5.67 | Q19: =H19*D24 -> 20.412 | R19: =+K19+L19+M19+O19 -> 46.494 | T19: =R19/H19 -> 0.205 | U19: =J19/H19 -> 0.35 | V19: =I19/H19 -> 0.325 | X19: =SUM(T19:V19) -> 0.88
A20: cebolla B | B20: 25 gms | C20: 17 | D20: =C20/C17 -> 0.085 | F20: 2 | G20: 12 | H20: =G20*28.35 -> 340.2 | I20: =H20*D19 -> 110.565 | J20: =H20*D25 -> 119.07 | K20: =H20*D20 -> 28.917 | L20: =H20*D23 -> 13.608 | M20: =H20*D21 -> 23.814 | N20: =H20*D26 -> 1.701 | O20: =H20*D22 -> 3.402 | P20: =H20*D27 -> 8.505 | Q20: =H20*D24 -> 30.618 | R20: =+K20+L20+M20+N20+O20+P20+Q20 -> 110.565 | T20: =R20/H20 -> 0.325 | U20: =J20/H20 -> 0.35 | V20: =I20/H20 -> 0.325 | X20: =SUM(T20:V20) -> 1
A21: chile dulce | B21: 10gms | C21: 14 | D21: =C21/C17 -> 0.07 | F21: 3 | G21: 16 | H21: =G21*28.35 -> 453.6 | I21: =H21*D19 -> 147.42 | J21: =H21*D25 -> 158.76 | K21: =H21*D20 -> 38.556 | L21: =H21*D23 -> 18.144 | M21: =H21*D21 -> 31.752 | N21: =H21*D26 -> 2.268 | O21: =H21*D22 -> 4.536 | P21: =H21*D27 -> 11.34 | Q21: =H21*D24 -> 40.824 | R21: =+K21+L21+M21+N21+O21+P21+Q21 -> 147.42 | T21: =R21/H21 -> 0.325 | U21: =J21/H21 -> 0.35 | V21: =I21/H21 -> 0.325 | X21: =SUM(T21:V21) -> 1
A22: apio | B22: 2gms | C22: 2 | D22: =C22/C17 -> 0.01 | F22: 4 | G22: 22 | H22: =G22*28.35 -> 623.7 | I22: =H22*D19 -> 202.7025 | J22: =H22*D25 -> 218.295 | K22: =H22*D20 -> 53.0145 | L22: =H22*D23 -> 24.948 | M22: =H22*D21 -> 43.659 | N22: =H22*D26 -> 3.1185 | O22: =H22*D22 -> 6.237 | P22: =H22*D27 -> 15.5925 | Q22: =H22*D24 -> 56.133 | R22: =+K22+L22+M22+N22+O22+P22+Q22 -> 202.7025 | T22: =R22/H22 -> 0.325 | U22: =J22/H22 -> 0.35 | V22: =I22/H22 -> 0.325 | X22: =SUM(T22:V22) -> 1
A23: culantro | B23: 5 gms | C23: 8 | D23: =C23/C17 -> 0.04
A24: Mango/ Piña | B24: 20gms | C24: 18 | D24: =C24/C17 -> 0.09 | G24: Precios
A25: caldo | B25: 1 de 4 oz | C25: 70 | D25: =C25/C17 -> 0.35 | G25: Oz | H25: Gr | I25: Precio | J25: Precio/ OZ | K25: Precio /gr pescado | L25: Costo Pescado | M25: Margen | O25: Precio de Pescado
A26: Gengibre | B26: 1 gr | C26: 1 | D26: =C26/C17 -> 0.005 | F26: 1 | G26: 8 | H26: =G26*28.35 -> 226.8 | I26: 2750 | J26: =I26/G26 -> 343.75 | K26: =I26/I19 -> 37.308371 | L26: =I19*V28 -> 731.78993 | M26: =(I26-L26)/I26 -> 0.73389457 | O26: Tambor de pescado de 5 Litros / 3kg de pescado = | V26: 29783.88
A27: Cebolla Morada | B27: 2 gr | C27: 5 | D27: =C27/C17 -> 0.025 | F27: 2 | G27: 12 | H27: =G27*28.35 -> 340.2 | I27: 3900 | J27: =I27/G27 -> 325 | K27: =I27/I20 -> 35.273369 | L27: =I20*V28 -> 1097.6849 | M27: =(I27-L27)/I27 -> 0.71854233 | O27: Precio Kilo de Pescado | V27: =V26/3 -> 9927.96
C28: =+C19+C20+C21+C22+C23+C26+C25+C27+C24 -> 200 | D28: =+D19+D20+D21+D22+D23+D26+D25+D27+D24 -> 1 | F28: 3 | G28: 16 | H28: =G28*28.35 -> 453.6 | I28: 4950 | J28: =I28/G28 -> 309.375 | K28: =I28/I21 -> 33.577534 | L28: =I21*V28 -> 1463.5799 | M28: =(I28-L28)/I28 -> 0.7043273 | O28: Precio/ gramo | V28: =V27/1000 -> 9.92796
F29: 4 | G29: 22 | H29: =G29*28.35 -> 623.7 | I29: 6950 | J29: =I29/G29 -> 315.90909 | K29: =I29/I22 -> 34.286701 | L29: =I22*V28 -> 2012.4223 | M29: =(I29-L29)/I29 -> 0.71044283
A31: MIXTO (Pescado+Camaron)
A32: presentacion | B32: 200gms | C32: 200 | F32: 3. Ceviche de Camaron | T32: % Ingredientes
B33: Original | G33: Oz | H33: Gr | I33: Pescado | J33: Caldo | K33: Cebolla B | L33: Culantro | M33: Chile D | N33: Gengibre | O33: Apio | P33: Cebolla M | Q33: Otro* | R33: Total Picadura | T33: Picadura | U33: Caldo | V33: Pescado | W33: Otro | X33: Total
A34: Pescado | B34: 90gms | C34: 60 | D34: =C34/C32 -> 0.3 | F34: 1 | G34: 8 | H34: =G34*28.35 -> 226.8 | I34: =H34*D34 -> 68.04 | J34: =H34*D40 -> 79.38 | K34: =H34*D35 -> 19.278 | L34: =H34*D38 -> 9.072 | M34: =H34*D36 -> 15.876 | N34: =H34*D41 -> 1.134 | O34: =H34*D37 -> 2.268 | P34: =H34*D42 -> 3.402 | Q34: =H34*D39 -> 28.35 | R34: =+K34+L34+M34+N34+O34+P34 -> 51.03 | T34: =R34/H34 -> 0.225 | U34: =J34/H34 -> 0.35 | V34: =I34/H34 -> 0.3 | X34: =SUM(T34:V34) -> 0.875
A35: cebolla B | B35: 25 gms | C35: 17 | D35: =C35/C32 -> 0.085 | F35: 2 | G35: 12 | H35: =G35*28.35 -> 340.2 | I35: =H35*D34 -> 102.06 | J35: =H35*D40 -> 119.07 | K35: =H35*D35 -> 28.917 | L35: =H35*D38 -> 13.608 | M35: =H35*D36 -> 23.814 | N35: =H35*D41 -> 1.701 | O35: =H35*D37 -> 3.402 | P35: =H35*D42 -> 5.103 | Q35: =H35*D39 -> 42.525 | R35: =+K35+L35+M35+N35+O35+P35 -> 76.545 | T35: =R35/H35 -> 0.225 | U35: =J35/H35 -> 0.35 | V35: =I35/H35 -> 0.3 | X35: =SUM(T35:V35) -> 0.875
A36: chile dulce | B36: 10gms | C36: 14 | D36: =C36/C32 -> 0.07 | F36: 3 | G36: 16 | H36: =G36*28.35 -> 453.6 | I36: =H36*D34 -> 136.08 | J36: =H36*D40 -> 158.76 | K36: =H36*D35 -> 38.556 | L36: =H36*D38 -> 18.144 | M36: =H36*D36 -> 31.752 | N36: =H36*D41 -> 2.268 | O36: =H36*D37 -> 4.536 | P36: =H36*D42 -> 6.804 | Q36: =H36*D39 -> 56.7 | R36: =+K36+L36+M36+N36+O36+P36 -> 102.06 | T36: =R36/H36 -> 0.225 | U36: =J36/H36 -> 0.35 | V36: =I36/H36 -> 0.3 | X36: =SUM(T36:V36) -> 0.875
A37: apio | B37: 2gms | C37: 2 | D37: =C37/C32 -> 0.01 | F37: 4 | G37: 22 | H37: =G37*28.35 -> 623.7 | I37: =H37*D34 -> 187.11 | J37: =H37*D40 -> 218.295 | K37: =H37*D35 -> 53.0145 | L37: =H37*D38 -> 24.948 | M37: =H37*D36 -> 43.659 | N37: =H37*D41 -> 3.1185 | O37: =H37*D37 -> 6.237 | P37: =H37*D42 -> 9.3555 | Q37: =H37*D39 -> 77.9625 | R37: =+K37+L37+M37+N37+O37+P37 -> 140.3325 | T37: =R37/H37 -> 0.225 | U37: =J37/H37 -> 0.35 | V37: =I37/H37 -> 0.3 | X37: =SUM(T37:V37) -> 0.875
A38: culantro | B38: 5 gms | C38: 8 | D38: =C38/C32 -> 0.04 | Q38: camaron
A39: Camaron | B39: 20gms | C39: 25 | D39: =C39/C32 -> 0.125 | G39: Precios | O39: Precio de Pescado
A40: caldo | B40: 1 de 4 oz | C40: 70 | D40: =C40/C32 -> 0.35 | G40: Oz | H40: Gr | I40: Precio | J40: Precio/ OZ | K40: Costo pescado | L40: Precio Camaron | M40: Total Costo Inumos | N40: Margen | O40: Tambor de pescado de 5 Litros / 3kg de pescado = | V40: 29783.88
A41: Gengibre | B41: 1 gr | C41: 1 | D41: =C41/C32 -> 0.005 | F41: 1 | G41: 8 | H41: =G41*28.35 -> 226.8 | I41: 2950 | J41: =I41/G41 -> 368.75 | K41: =I34*V42 -> 675.4984 | L41: =Q34*V46 -> 356.6241 | M41: =K41+L41 -> 1032.1225 | N41: =(I41-M41)/I41 -> 0.65012797 | O41: Precio Kilo de Pescado | V41: =V40/3 -> 9927.96
A42: Cebolla Morada | B42: 2 gr | C42: 3 | D42: =C42/C32 -> 0.015 | F42: 2 | G42: 12 | H42: =G42*28.35 -> 340.2 | I42: 4100 | J42: =I42/G42 -> 341.66667 | K42: =I35*V42 -> 1013.2476 | L42: =Q35*V46 -> 534.93615 | M42: =K42+L42 -> 1548.1837 | N42: =(I42-M42)/I42 -> 0.62239421 | O42: Precio/ gramo | V42: =V41/1000 -> 9.92796
...

Sheet Mezcla picadura
D4: Mezcla base de picadura para ceviches ( 1 kg)
E6: Ingrediente | F6: Gramos | G6: % | H6: 1 kg
H7: 1000
D8: 1 | E8: Cebolla B | F8: 20 | G8: =F8/F14 -> 0.4 | H8: =H7*G8 -> 400
D9: 2 | E9: chile dulce | F9: 17 | G9: =F9/F14 -> 0.34 | H9: =H7*G9 -> 340
D10: 3 | E10: apio | F10: 2 | G10: =F10/F14 -> 0.04 | H10: =H7*G10 -> 40
D11: 4 | E11: culantro | F11: 10 | G11: =F11/F14 -> 0.2 | H11: =H7*G11 -> 200
D12: 5 | E12: Gengibre | F12: 1 | G12: =F12/F14 -> 0.02 | H12: =H7*G12 -> 20
D13: 6 | E13: Cebolla Morada
F14: =SUM(F8:F12) -> 50 | G14: =SUM(G8:G12) -> 1 | H14: =SUM(H8:H12) -> 1000

Sheet Mezcla final
D1: Gramos de ingredientes por Ceviche y Tamaño
F2: Menú
D3: Tamaño | E3: Ingredientes | F3: Clásico | G3: Tropical | H3: Mixto | I3: Camarón
D4: 8 Onz | E4: Pescado | F4: ='Mezclas por tamaño'!I4 -> 85.05 | G4: ='Mezclas por tamaño'!I19 -> 73.71
E5: Picadura | F5: ='Mezclas por tamaño'!R4 -> 55.566
E6: Caldo | F6: ='Mezclas por tamaño'!J4 -> 79.38
E7: Cebolla Morada | F7: ='Mezclas por tamaño'!P4 -> 5.67
E8: Gengibre | F8: ='Mezclas por tamaño'!N4 -> 1.134
E9: Camarón
E10: Mango / Piña
D12: 12 Onz | E12: Pescado | F12: ='Mezclas por tamaño'!I5 -> 127.575
E13: Picadura | F13: ='Mezclas por tamaño'!R5 -> 83.349
E14: Caldo | F14: ='Mezclas por tamaño'!J5 -> 119.07
E15: Cebolla Morada | F15: ='Mezclas por tamaño'!P5 -> 8.505
E16: Gengibre | F16: ='Mezclas por tamaño'!N5 -> 1.701
E17: Camarón
E18: Mango/ Piña
D20: 16 Onz | E20: Pescado | F20: ='Mezclas por tamaño'!I6 -> 170.1
E21: Picadura | F21: ='Mezclas por tamaño'!R6 -> 111.132
E22: Caldo | F22: ='Mezclas por tamaño'!J6 -> 158.76
E23: Cebolla Morada | F23: ='Mezclas por tamaño'!P6 -> 11.34
E24: Gengibre | F24: ='Mezclas por tamaño'!N6 -> 2.268
E25: Camarón
E26: Mango / Piña
D28: 22 Onz | E28: Pescado | F28: ='Mezclas por tamaño'!I7 -> 233.8875
E29: Picadura | F29: ='Mezclas por tamaño'!R7 -> 152.8065
E30: Caldo | F30: ='Mezclas por tamaño'!J7 -> 218.295
E31: Cebolla Morada | F31: ='Mezclas por tamaño'!P7 -> 15.5925
E32: Gengibre | F32: ='Mezclas por tamaño'!N7 -> 3.1185
E33: Camarón
E34: Mango / Piña

Sheet MENU PRECIOS
C2: LA ESQUINITA
C3: MENÚ | D3: Pequeño | E3: Mediano | F3: Grande | G3: Familiar
D4: 8 ONZ | E4: 12 ONZ | F4: 16 ONZ | G4: 22 ONZ
C5: TROPICAL | D5: 2750 | E5: 3900 | F5: 4950 | G5: 6950
C7: CLASICO Pescado | D7: 2850 | E7: 4200 | F7: 5350 | G7: 7100
C9: MIXTO Camaron Pescado | D9: 2950 | E9: 4100 | F9: 5450 | G9: 7400
C11: CAMARON | D11: 3350 | E11: 4950 | F11: 6550 | G11: 7950

Sheet Precios Competencia
